<?xml version="1.0" encoding="utf-8"?>
<!-- This URDF was automatically created by SolidWorks to URDF Exporter! Originally created by Stephen Brawner (brawner@gmail.com) 
     Commit Version: 1.6.0-4-g7f85cfe  Build Version: 1.6.7995.38578
     For more information, please see http://wiki.ros.org/sw_urdf_exporter -->
<robot
  name="bicycle_urdf">
  <link
    name="base_link">
    <visual>
      <origin
        xyz="0 0 0"
        rpy="0 0 0" />
      <geometry>
        <mesh
          filename="package://bicycle_urdf/meshes/base_link.STL" />
      </geometry>
      <material
        name="">
        <color
          rgba="1 1 1 1" />
      </material>
    </visual>
    <collision>
      <origin
        xyz="0 0 0"
        rpy="0 0 0" />
      <geometry>
        <mesh
          filename="package://bicycle_urdf/meshes/base_link.STL" />
      </geometry>
    </collision>
  </link>
  <link
    name="j1">
    <inertial>
      <origin
        xyz="0.015473 -0.00077799 0.5819"
        rpy="0 0 0" />
      <mass
        value="3.6404" />
      <inertia
        ixx="0.053969"
        ixy="3.96E-05"
        ixz="-0.039018"
        iyy="0.14785"
        iyz="-2.2259E-06"
        izz="0.097779" />
    </inertial>
    <visual>
      <origin
        xyz="0 0 0"
        rpy="0 0 0" />
      <geometry>
        <mesh
          filename="package://bicycle_urdf/meshes/j1.dae" />
      </geometry>
      <material
        name="">
        <color
          rgba="1 1 1 1" />
      </material>
    </visual>
    <collision>
      <origin
        xyz="0 0 0"
        rpy="0 0 0" />
      <geometry>
        <mesh
          filename="package://bicycle_urdf/meshes/j1.dae" />
      </geometry>
    </collision>
  </link>
  <joint
    name="j1"
    type="revolute">
    <origin
      xyz="0 0 0"
      rpy="0 0 0" />
    <parent
      link="base_link" />
    <child
      link="j1" />
    <axis
      xyz="1 0 0" />
    <limit
      lower="-1.57"
      upper="1.57"
      effort="0"
      velocity="0" />
  </joint>
  <link
    name="j2">
    <inertial>
      <origin
        xyz="0.012509 -0.00053714 -0.19226"
        rpy="0 0 0" />
      <mass
        value="0.68174" />
      <inertia
        ixx="0.0042946"
        ixy="-3.0303E-08"
        ixz="4.5338E-06"
        iyy="0.0034463"
        iyz="9.0055E-09"
        izz="0.00099221" />
    </inertial>
    <visual>
      <origin
        xyz="0 0 0"
        rpy="0 0 0" />
      <geometry>
        <mesh
          filename="package://bicycle_urdf/meshes/j2.dae" />
      </geometry>
      <material
        name="">
        <color
          rgba="1 1 1 1" />
      </material>
    </visual>
    <collision>
      <origin
        xyz="0 0 0"
        rpy="0 0 0" />
      <geometry>
        <mesh
          filename="package://bicycle_urdf/meshes/j2.dae" />
      </geometry>
    </collision>
  </link>
  <joint
    name="j2"
    type="revolute">
    <origin
      xyz="0.38509 0.000175 0.89724"
      rpy="0 -0.312 0" />
    <parent
      link="j1" />
    <child
      link="j2" />
    <axis
      xyz="0 0 -1" />
    <limit
      lower="-1.57"
      upper="1.57"
      effort="0"
      velocity="0" />
  </joint>
  <link
    name="j6">
    <inertial>
      <origin
        xyz="-0.00054858 0.00024903 -6.0281E-05"
        rpy="0 0 0" />
      <mass
        value="0.044753" />
      <inertia
        ixx="2.7275E-05"
        ixy="2.4489E-07"
        ixz="-1.0126E-09"
        iyy="3.9444E-06"
        iyz="-2.93E-09"
        izz="2.736E-05" />
    </inertial>
    <visual>
      <origin
        xyz="0 0 0"
        rpy="0 0 0" />
      <geometry>
        <mesh
          filename="package://bicycle_urdf/meshes/j6.dae" />
      </geometry>
      <material
        name="">
        <color
          rgba="1 1 1 1" />
      </material>
    </visual>
    <collision>
      <origin
        xyz="0 0 0"
        rpy="0 0 0" />
      <geometry>
        <mesh
          filename="package://bicycle_urdf/meshes/j6.dae" />
      </geometry>
    </collision>
  </link>
  <joint
    name="j6"
    type="fixed">
    <origin
      xyz="0.068861 -0.00088133 0.018549"
      rpy="0 0.17453 0" />
    <parent
      link="j2" />
    <child
      link="j6" />
    <axis
      xyz="0 0 0" />
  </joint>
  <link
    name="j3">
    <inertial>
      <origin
        xyz="7.5754E-06 -4.6249E-05 -0.0003164"
        rpy="0 0 0" />
      <mass
        value="1.4336" />
      <inertia
        ixx="0.07015"
        ixy="-2.4297E-08"
        ixz="-4.9239E-05"
        iyy="0.14017"
        iyz="2.6741E-07"
        izz="0.070164" />
    </inertial>
    <visual>
      <origin
        xyz="0 0 0"
        rpy="0 0 0" />
      <geometry>
        <mesh
          filename="package://bicycle_urdf/meshes/j3.dae" />
      </geometry>
      <material
        name="">
        <color
          rgba="1 1 1 1" />
      </material>
    </visual>
    <collision>
      <origin
        xyz="0 0 0"
        rpy="0 0 0" />
      <geometry>
        <mesh
          filename="package://bicycle_urdf/meshes/j3.dae" />
      </geometry>
    </collision>
  </link>
  <joint
    name="j3"
    type="revolute">
    <origin
      xyz="0.00011884 -0.001 -0.5832"
      rpy="0 0.312 0" />
    <parent
      link="j2" />
    <child
      link="j3" />
    <axis
      xyz="0 1 0" />
    <limit
      lower="-3.14"
      upper="3.14"
      effort="0"
      velocity="0" />
  </joint>
  <link
    name="j4">
    <inertial>
      <origin
        xyz="-3.8345E-05 -0.00021809 -0.00030458"
        rpy="0 0 0" />
      <mass
        value="1.4778" />
      <inertia
        ixx="0.070308"
        ixy="-5.1529E-08"
        ixz="4.9621E-05"
        iyy="0.14042"
        iyz="-2.6307E-07"
        izz="0.070301" />
    </inertial>
    <visual>
      <origin
        xyz="0 0 0"
        rpy="0 0 0" />
      <geometry>
        <mesh
          filename="package://bicycle_urdf/meshes/j4.dae" />
      </geometry>
      <material
        name="">
        <color
          rgba="1 1 1 1" />
      </material>
    </visual>
    <collision>
      <origin
        xyz="0 0 0"
        rpy="0 0 0" />
      <geometry>
        <mesh
          filename="package://bicycle_urdf/meshes/j4.dae" />
      </geometry>
    </collision>
  </link>
  <joint
    name="j4"
    type="revolute">
    <origin
      xyz="-0.42413 0 0.3425"
      rpy="0 0 0" />
    <parent
      link="j1" />
    <child
      link="j4" />
    <axis
      xyz="0 -1 0" />
    <limit
      lower="-3.14"
      upper="3.14"
      effort="0"
      velocity="0" />
  </joint>
  <link
    name="j5">
    <inertial>
      <origin
        xyz="0.0014631 0.00022537 8.6819E-05"
        rpy="0 0 0" />
      <mass
        value="0.037231" />
      <inertia
        ixx="1.6788E-05"
        ixy="-4.3096E-08"
        ixz="-4.7953E-07"
        iyy="1.4823E-05"
        iyz="5.8388E-09"
        izz="3.0114E-05" />
    </inertial>
    <visual>
      <origin
        xyz="0 0 0"
        rpy="0 0 0" />
      <geometry>
        <mesh
          filename="package://bicycle_urdf/meshes/j5.dae" />
      </geometry>
      <material
        name="">
        <color
          rgba="1 1 1 1" />
      </material>
    </visual>
    <collision>
      <origin
        xyz="0 0 0"
        rpy="0 0 0" />
      <geometry>
        <mesh
          filename="package://bicycle_urdf/meshes/j5.dae" />
      </geometry>
    </collision>
  </link>
  <joint
    name="j5"
    type="fixed">
    <origin
      xyz="0.48435 0.00017515 0.84618"
      rpy="0 0 0" />
    <parent
      link="j1" />
    <child
      link="j5" />
    <axis
      xyz="0 0 0" />
  </joint>
</robot>
